Workbook

Sheet Tabla de Inversion
E9: MOB Y EQUIPO | F9: 83025
E10: EQUIPO DE COMPUTO | F10: 3000
E11: ENSERES | F11: 12732
E12: EQ. OFICINA | F12: 8089

Sheet VENTAS
A2: 2020
A3: CONCEPTO | B3: COSTO | C3: PERSONAL REQUERIDO | D3: ENERO | E3: FEBRERO | F3: MARZO | G3: ABRIL | H3: MAYO | I3: JUNIO | J3: JULIO | K3: AGOSTO | L3: SEPTIEMBRE | M3: OCTUBRE | N3: NOVIEMBRE | O3: DICIEMBRE | P3: TOTAL
A4: MANICURE | B4: 150 | C4: 4 | D4: =15*C4*B4 -> 9000 | E4: =20*C4*B4 -> 12000 | F4: =20*C4*B4 -> 12000 | G4: =10*C4*B4 -> 6000 | H4: =18*C4*B4 -> 10800 | I4: =8*C4*B4 -> 4800 | J4: =19*C4*B4 -> 11400 | K4: =15*C4*B4 -> 9000 | L4: =20*C4*B4 -> 12000 | M4: =15*C4*B4 -> 9000 | N4: =15*C4*B4 -> 9000 | O4: =16*C4*B4 -> 9600 | P4: =SUM(D4:O4) -> 114600
A5: PEDICURE | B5: 200 | C5: 4 | D5: =5*$C$5*$B$5 -> 4000 | E5: =20*$C$5*$B$5 -> 16000 | F5: =18*$C$5*$B$5 -> 14400 | G5: =12*$C$5*$B$5 -> 9600 | H5: =3*$C$5*$B$5 -> 2400 | I5: =3*$C$5*$B$5 -> 2400 | J5: =5*$C$5*$B$5 -> 4000 | K5: =8*$C$5*$B$5 -> 6400 | L5: =8*$C$5*$B$5 -> 6400 | M5: =5*$C$5*$B$5 -> 4000 | N5: =5*$C$5*$B$5 -> 4000 | O5: =5*$C$5*$B$5 -> 4000 | P5: =SUM(D5:O5) -> 77600
A6: FACIALES | B6: 300 | C6: 4 | D6: =2*$C$6*$B$6 -> 2400 | E6: =2*$C$6*$B$6 -> 2400 | F6: =3*$C$6*$B$6 -> 3600 | G6: =3*$C$6*$B$6 -> 3600 | H6: =1*$C$6*$B$6 -> 1200 | I6: =1*$C$6*$B$6 -> 1200 | J6: =1*$C$6*$B$6 -> 1200 | K6: =2*$C$6*$B$6 -> 2400 | L6: =6*$C$6*$B$6 -> 7200 | M6: =7*$C$6*$B$6 -> 8400 | N6: =3*$C$6*$B$6 -> 3600 | O6: =3*$C$6*$B$6 -> 3600 | P6: =SUM(D6:O6) -> 40800
A7: DEPILACIONES | B7: 200 | C7: 1 | D7: =65*$C$7*$B$7 -> 13000 | E7: =80*$C$7*$B$7 -> 16000 | F7: =70*$C$7*$B$7 -> 14000 | G7: =75*$C$7*$B$7 -> 15000 | H7: =80*$C$7*$B$7 -> 16000 | I7: =74*$C$7*$B$7 -> 14800 | J7: =30*$C$7*$B$7 -> 6000 | K7: =72*$C$7*$B$7 -> 14400 | L7: =100*$C$7*$B$7 -> 20000 | M7: =100*$C$7*$B$7 -> 20000 | N7: =90*$C$7*$B$7 -> 18000 | O7: =90*$C$7*$B$7 -> 18000 | P7: =SUM(D7:O7) -> 185200
A8: APAR. 50% (CONTADO) | B8: 1600 | C8: 1 | D8: =3*$C$8*$B$8 -> 4800 | E8: =3*$C$8*$B$8 -> 4800 | F8: =5*$C$8*$B$8 -> 8000 | G8: =7*$C$8*$B$8 -> 11200 | H8: =8*$C$8*$B$8 -> 12800 | I8: =4*$C$8*$B$8 -> 6400 | J8: =3*$C$8*$B$8 -> 4800 | K8: =4*$C$8*$B$8 -> 6400 | L8: =6*$C$8*$B$8 -> 9600 | M8: =5*$C$8*$B$8 -> 8000 | N8: =4*$C$8*$B$8 -> 6400 | O8: =4*$C$8*$B$8 -> 6400 | P8: =SUM(D8:O8) -> 89600
A9: APAR. 50% (15 DÍAS) | B9: 1600 | C9: 1 | D9: 0 | E9: =D8 -> 4800 | F9: =E8 -> 4800 | G9: =F8 -> 8000 | H9: =G8 -> 11200 | I9: =H8 -> 12800 | J9: =I8 -> 6400 | K9: =J8 -> 4800 | L9: =K8 -> 6400 | ... O9: =N8 -> 6400 | P9: =SUM(D9:O9) -> 83200
A10: SESIONES APARTO. | B10: 350 | C10: 1 | D10: =20*$C$10*$B$10 -> 7000 | E10: =13*$C$10*$B$10 -> 4550 | F10: =10*$C$10*$B$10 -> 3500 | G10: =0*$C$10*$B$10 -> 0 | H10: =0*$C$10*$B$10 -> 0 | I10: =4*$C$10*$B$10 -> 1400 | J10: =5*$C$10*$B$10 -> 1750 | K10: =8*$C$10*$B$10 -> 2800 | L10: =0*$C$10*$B$10 -> 0 | M10: =8*$C$10*$B$10 -> 2800 | N10: =0*$C$10*$B$10 -> 0 | O10: =12*$C$10*$B$10 -> 4200 | P10: =SUM(D10:O10) -> 28000
A11: RADIO FACIAL | B11: 250 | C11: 1 | D11: =4*$C$11*$B$11 -> 1000 | E11: =16*$C$11*$B$11 -> 4000 | F11: =40*$C$11*$B$11 -> 10000 | G11: =28*$C$11*$B$11 -> 7000 | H11: =22*$C$11*$B$11 -> 5500 | I11: =24*$C$11*$B$11 -> 6000 | J11: =50*$C$11*$B$11 -> 12500 | K11: =60*$C$11*$B$11 -> 15000 | L11: =25*$C$11*$B$11 -> 6250 | M11: =24*$C$11*$B$11 -> 6000 | N11: =24*$C$11*$B$11 -> 6000 | O11: =50*$C$11*$B$11 -> 12500 | P11: =SUM(D11:O11) -> 91750
A12: MASAJES | B12: 500 | C12: 1 | D12: =8*$C$12*$B$12 -> 4000 | E12: =13*$C$12*$B$12 -> 6500 | F12: =15*$C$12*$B$12 -> 7500 | G12: =4*$C$12*$B$12 -> 2000 | H12: =16*$C$12*$B$12 -> 8000 | I12: =5*$C$12*$B$12 -> 2500 | J12: =8*$C$12*$B$12 -> 4000 | K12: =6*$C$12*$B$12 -> 3000 | L12: =13*$C$12*$B$12 -> 6500 | M12: =9*$C$12*$B$12 -> 4500 | N12: =28*$C$12*$B$12 -> 14000 | O12: =10*$C$12*$B$12 -> 5000 | P12: =SUM(D12:O12) -> 67500
A13: PTO ENTRADAS | D13: =D4+D5+D6+D7+D8+D10+D11+D12+D9 -> 45200 | E13: =E4+E5+E6+E7+E8+E10+E11+E12+E9 -> 71050 | F13: =F4+F5+F6+F7+F8+F10+F11+F12+F9 -> 77800 | G13: =G4+G5+G6+G7+G8+G10+G11+G12+G9 -> 62400 | H13: =H4+H5+H6+H7+H8+H10+H11+H12+H9 -> 67900 | I13: =I4+I5+I6+I7+I8+I10+I11+I12+I9 -> 52300 | J13: =J4+J5+J6+J7+J8+J10+J11+J12+J9 -> 52050 | K13: =K4+K5+K6+K7+K8+K10+K11+K12+K9 -> 64200 | ... O13: =O4+O5+O6+O7+O8+O10+O11+O12+O9 -> 69700 | P13: =SUM(D13:O13) -> 778250
A14: VENTAS | D14: =D4+D5+D6+D7+D8+E9+D10+D11+D12 -> 50000 | E14: =E4+E5+E6+E7+E8+F9+E10+E11+E12 -> 71050 | F14: =F4+F5+F6+F7+F8+G9+F10+F11+F12 -> 81000 | G14: =G4+G5+G6+G7+G8+H9+G10+G11+G12 -> 65600 | H14: =H4+H5+H6+H7+H8+I9+H10+H11+H12 -> 69500 | I14: =I4+I5+I6+I7+I8+J9+I10+I11+I12 -> 45900 | J14: =J4+J5+J6+J7+J8+K9+J10+J11+J12 -> 50450 | K14: =K4+K5+K6+K7+K8+L9+K10+K11+K12 -> 65800 | ... N14: =N4+N5+N6+N7+N8+O9+N10+N11+N12 -> 67400 | O14: =O4+O5+O6+O7+O8+D27+O10+O11+O12 -> 69700 | P14: =SUM(D14:O14) -> 784650
A16: VENTAS INFLACIÓN | D16: =D14*1.05 -> 52500 | E16: =E14*1.05 -> 74602.5 | F16: =F14*1.05 -> 85050 | G16: =G14*1.05 -> 68880 | H16: =H14*1.05 -> 72975 | I16: =I14*1.05 -> 48195 | J16: =J14*1.05 -> 52972.5 | K16: =K14*1.05 -> 69090 | ... O16: =O14*1.05 -> 73185 | P16: =SUM(D16:O16) -> 823882.5
A17: AUMENTO 10% | D17: =D16*1.1 -> 57750 | E17: =E16*1.1 -> 82062.75 | F17: =F16*1.1 -> 93555 | G17: =G16*1.1 -> 75768 | H17: =H16*1.1 -> 80272.5 | I17: =I16*1.1 -> 53014.5 | J17: =J16*1.1 -> 58269.75 | K17: =K16*1.1 -> 75999 | ... O17: =O16*1.1 -> 80503.5 | P17: =SUM(D17:O17) -> 906270.75
A20: 2021
A21: CONCEPTO | B21: COSTO | C21: PERSONAL REQUERIDO | D21: ENERO | E21: FEBRERO | F21: MARZO | G21: ABRIL | H21: MAYO | I21: JUNIO | J21: JULIO | K21: AGOSTO | L21: SEPTIEMBRE | M21: OCTUBRE | N21: NOVIEMBRE | O21: DICIEMBRE | P21: TOTAL
A22: MANICURE | B22: 157.5 | C22: 1 | D22: =32*$C$22*$B$22 -> 5040 | E22: =40*$C$22*$B$22 -> 6300 | F22: =60*$C$22*$B$22 -> 9450 | G22: =40*$C$22*$B$22 -> 6300 | H22: =60*$C$22*$B$22 -> 9450 | I22: =60*$C$22*$B$22 -> 9450 | J22: =40*$C$22*$B$22 -> 6300 | K22: =45*$C$22*$B$22 -> 7087.5 | L22: =50*$C$22*$B$22 -> 7875 | M22: =50*$C$22*$B$22 -> 7875 | N22: =50*$C$22*$B$22 -> 7875 | O22: =70*$C$22*$B$22 -> 11025 | P22: =SUM(D22:O22) -> 94027.5
A23: PEDICURE | B23: 210 | C23: 1 | D23: =13*$C$23*$B$23 -> 2730 | E23: =12*$C$23*$B$23 -> 2520 | F23: =33*$C$23*$B$23 -> 6930 | G23: =40*$C$23*$B$23 -> 8400 | H23: =40*$C$23*$B$23 -> 8400 | I23: =8*$C$23*$B$23 -> 1680 | J23: =25*$C$23*$B$23 -> 5250 | K23: =20*$C$23*$B$23 -> 4200 | L23: =35*$C$23*$B$23 -> 7350 | M23: =15*$C$23*$B$23 -> 3150 | N23: =50*$C$23*$B$23 -> 10500 | O23: =45*$C$23*$B$23 -> 9450 | P23: =SUM(D23:O23) -> 70560
A24: FACIALES | B24: 315 | C24: 1 | D24: =8*$C$24*$B$24 -> 2520 | E24: =9*$C$24*$B$24 -> 2835 | F24: =18*$C$24*$B$24 -> 5670 | G24: =16*$C$24*$B$24 -> 5040 | H24: =18*$C$24*$B$24 -> 5670 | I24: =4*$C$24*$B$24 -> 1260 | J24: =20*$C$24*$B$24 -> 6300 | K24: =30*$C$24*$B$24 -> 9450 | L24: =18*$C$24*$B$24 -> 5670 | M24: =15*$C$24*$B$24 -> 4725 | N24: =30*$C$24*$B$24 -> 9450 | O24: =30*$C$24*$B$24 -> 9450 | P24: =SUM(D24:O24) -> 68040
A25: DEPILACIONES | B25: 210 | C25: 1 | D25: =80*$C$25*$B$25 -> 16800 | E25: =90*$C$25*$B$25 -> 18900 | F25: =100*$C$25*$B$25 -> 21000 | G25: =70*$C$25*$B$25 -> 14700 | H25: =85*$C$25*$B$25 -> 17850 | I25: =70*$C$25*$B$25 -> 14700 | J25: =80*$C$25*$B$25 -> 16800 | K25: =90*$C$25*$B$25 -> 18900 | L25: =110*$C$25*$B$25 -> 23100 | M25: =90*$C$25*$B$25 -> 18900 | N25: =70*$C$25*$B$25 -> 14700 | O25: =80*$C$25*$B$25 -> 16800 | P25: =SUM(D25:O25) -> 213150
A26: APAR. 50% (CONTADO) | B26: 1575 | C26: 1 | D26: =3*$C$26*$B$26 -> 4725 | E26: =5*$C$26*$B$26 -> 7875 | F26: =6*$C$26*$B$26 -> 9450 | G26: =8*$C$26*$B$26 -> 12600 | H26: =5*$C$26*$B$26 -> 7875 | I26: =3*$C$26*$B$26 -> 4725 | J26: =5*$C$26*$B$26 -> 7875 | K26: =4*$C$26*$B$26 -> 6300 | L26: =4*$C$26*$B$26 -> 6300 | M26: =5*$C$26*$B$26 -> 7875 | N26: =3*$C$26*$B$26 -> 4725 | O26: =4*$C$26*$B$26 -> 6300 | P26: =SUM(D26:O26) -> 86625
A27: APAR. 50% (15 DÍAS) | B27: 1575 | C27: 1 | D27: =O8 -> 6400 | E27: =D26 -> 4725 | F27: =E26 -> 7875 | G27: =F26 -> 9450 | H27: =G26 -> 12600 | I27: =H26 -> 7875 | J27: =I26 -> 4725 | K27: =J26 -> 7875 | L27: =K26 -> 6300 | ... O27: =N26 -> 4725 | P27: =SUM(D27:O27) -> 86725
A28: SESIONES APARTO. | B28: 367.5 | C28: 1 | D28: =13*$C$28*$B$28 -> 4777.5 | E28: =20*$C$28*$B$28 -> 7350 | F28: =8*$C$28*$B$28 -> 2940 | G28: =0*$C$28*$B$28 -> 0 | H28: =18*$C$28*$B$28 -> 6615 | I28: =0*$C$28*$B$28 -> 0 | J28: =12*$C$28*$B$28 -> 4410 | K28: =0*$C$28*$B$28 -> 0 | L28: =2*$C$28*$B$28 -> 735 | M28: =30*$C$28*$B$28 -> 11025 | N28: =25*$C$28*$B$28 -> 9187.5 | O28: =20*$C$28*$B$28 -> 7350 | P28: =SUM(D28:O28) -> 54390
A29: RADIO FACIAL | B29: 262.5 | C29: 1 | D29: =30*$C$29*$B$29 -> 7875 | E29: =30*$C$29*$B$29 -> 7875 | F29: =30*$C$29*$B$29 -> 7875 | G29: =30*$C$29*$B$29 -> 7875 | H29: =30*$C$29*$B$29 -> 7875 | I29: =10*$C$29*$B$29 -> 2625 | J29: =19*$C$29*$B$29 -> 4987.5 | K29: =25*$C$29*$B$29 -> 6562.5 | L29: =30*$C$29*$B$29 -> 7875 | M29: =17*$C$29*$B$29 -> 4462.5 | N29: =35*$C$29*$B$29 -> 9187.5 | O29: =30*$C$29*$B$29 -> 7875 | P29: =SUM(D29:O29) -> 82950
A30: MASAJES | B30: 525 | C30: 1 | D30: =18*$C$30*$B$30 -> 9450 | E30: =39*$C$30*$B$30 -> 20475 | F30: =40*$C$30*$B$30 -> 21000 | G30: =25*$C$30*$B$30 -> 13125 | H30: =35*$C$30*$B$30 -> 18375 | I30: =30*$C$30*$B$30 -> 15750 | J30: =35*$C$30*$B$30 -> 18375 | K30: =35*$C$30*$B$30 -> 18375 | L30: =50*$C$30*$B$30 -> 26250 | M30: =30*$C$30*$B$30 -> 15750 | N30: =16*$C$30*$B$30 -> 8400 | O30: =14*$C$30*$B$30 -> 7350 | P30: =SUM(D30:O30) -> 192675
A31: PTO ENTRADAS | D31: =D22+D23+D24+D25+D26+D27+D28+D29+D30 -> 60317.5 | E31: =E22+E23+E24+E25+E26+E27+E28+E29+E30 -> 78855 | F31: =F22+F23+F24+F25+F26+F27+F28+F29+F30 -> 92190 | G31: =G22+G23+G24+G25+G26+G27+G28+G29+G30 -> 77490 | H31: =H22+H23+H24+H25+H26+H27+H28+H29+H30 -> 94710 | I31: =I22+I23+I24+I25+I26+I27+I28+I29+I30 -> 58065 | J31: =J22+J23+J24+J25+J26+J27+J28+J29+J30 -> 75022.5 | K31: =K22+K23+K24+K25+K26+K27+K28+K29+K30 -> 78750 | ... O31: =O22+O23+O24+O25+O26+O27+O28+O29+O30 -> 80325 | P31: =SUM(D31:O31) -> 949142.5
A32: VENTAS | D32: =D22+D23+D24+D25+D26+E27+D28+D29+D30 -> 58642.5 | E32: =E22+E23+E24+E25+E26+F27+E28+E29+E30 -> 82005 | F32: =F22+F23+F24+F25+F26+G27+F28+F29+F30 -> 93765 | G32: =G22+G23+G24+G25+G26+H27+G28+G29+G30 -> 80640 | H32: =H22+H23+H24+H25+H26+I27+H28+H29+H30 -> 89985 | I32: =I22+I23+I24+I25+I26+J27+I28+I29+I30 -> 54915 | J32: =J22+J23+J24+J25+J26+K27+J28+J29+J30 -> 78172.5 | K32: =K22+K23+K24+K25+K26+L27+K28+K29+K30 -> 77175 | ... N32: =N22+N23+N24+N25+N26+O27+N28+N29+N30 -> 78750 | O32: =O22+O23+O24+O25+O26+D45+O28+O29+O30 -> 81900 | P32: =SUM(D32:O32) -> 949042.5
A34: VENTAS INFLACIÓN | D34: =D32*1.05 -> 61574.625 | E34: =E32*1.05 -> 86105.25 | F34: =F32*1.05 -> 98453.25 | G34: =G32*1.05 -> 84672 | H34: =H32*1.05 -> 94484.25 | I34: =I32*1.05 -> 57660.75 | J34: =J32*1.05 -> 82081.125 | K34: =K32*1.05 -> 81033.75 | ... O34: =O32*1.05 -> 85995 | P34: =SUM(D34:O34) -> 996494.62
A35: AUMENTO 10% | D35: =D34*1.1 -> 67732.088 | E35: =E34*1.1 -> 94715.775 | F35: =F34*1.1 -> 108298.58 | G35: =G34*1.1 -> 93139.2 | H35: =H34*1.1 -> 103932.68 | I35: =I34*1.1 -> 63426.825 | J35: =J34*1.1 -> 90289.238 | K35: =K34*1.1 -> 89137.125 | ... O35: =O34*1.1 -> 94594.5 | P35: =SUM(D35:O35) -> 1096144.1
A38: 2022
A39: CONCEPTO | B39: COSTO | C39: PERSONAL REQUERIDO | D39: ENERO | E39: FEBRERO | F39: MARZO | G39: ABRIL | H39: MAYO | I39: JUNIO | J39: JULIO | K39: AGOSTO | L39: SEPTIEMBRE | M39: OCTUBRE | N39: NOVIEMBRE | O39: DICIEMBRE | P39: TOTAL | S39: ENERO | T39: FEBRERO | U39: MARZO | V39: ABRIL | W39: MAYO | X39: JUNIO | Y39: JULIO | Z39: AGOSTO | AA39: SEPTIEMBRE | AB39: OCTUBRE | AC39: NOVIEMBRE | AD39: DICIEMBRE
A40: MANICURE | B40: 165.38 | C40: 1 | D40: =S40*$C$40*$B$40 -> 4961.4 | E40: =T40*$C$40*$B$40 -> 4961.4 | F40: =U40*$C$40*$B$40 -> 9922.8 | G40: =V40*$C$40*$B$40 -> 8269 | H40: =W40*$C$40*$B$40 -> 9922.8 | I40: =X40*$C$40*$B$40 -> 5788.3 | J40: =Y40*$C$40*$B$40 -> 8269 | K40: =Z40*$C$40*$B$40 -> 6615.2 | ... O40: =AD40*$C$40*$B$40 -> 11576.6 | P40: =SUM(D40:O40) -> 92612.8 | S40: 30 | T40: 30 | U40: 60 | V40: 50 | W40: 60 | X40: 35 | Y40: 50 | Z40: 40 | AA40: 40 | AB40: 45 | AC40: 50 | AD40: 70
A41: PEDICURE | B41: 220.5 | C41: 1 | D41: =S41*$C$41*$B$41 -> 4410 | E41: =T41*$C$41*$B$41 -> 4410 | F41: =U41*$C$41*$B$41 -> 9922.5 | G41: =V41*$C$41*$B$41 -> 6615 | H41: =W41*$C$41*$B$41 -> 8820 | I41: =X41*$C$41*$B$41 -> 6615 | J41: =Y41*$C$41*$B$41 -> 0 | K41: =Z41*$C$41*$B$41 -> 4410 | ... O41: =AD41*$C$41*$B$41 -> 9922.5 | P41: =SUM(D41:O41) -> 77395.5 | S41: 20 | T41: 20 | U41: 45 | V41: 30 | W41: 40 | X41: 30 | Y41: 0 | Z41: 20 | AA41: 28 | AB41: 28 | AC41: 45 | AD41: 45
A42: FACIALES | B42: 330.75 | C42: 1 | D42: =S42*$C$42*$B$42 -> 8268.75 | E42: =T42*$C$42*$B$42 -> 6615 | F42: =U42*$C$42*$B$42 -> 11576.25 | G42: =V42*$C$42*$B$42 -> 8268.75 | H42: =W42*$C$42*$B$42 -> 6615 | I42: =X42*$C$42*$B$42 -> 4961.25 | J42: =Y42*$C$42*$B$42 -> 9922.5 | K42: =Z42*$C$42*$B$42 -> 8268.75 | ... O42: =AD42*$C$42*$B$42 -> 6615 | P42: =SUM(D42:O42) -> 95256 | S42: 25 | T42: 20 | U42: 35 | V42: 25 | W42: 20 | X42: 15 | Y42: 30 | Z42: 25 | AA42: 23 | AB42: 25 | AC42: 25 | AD42: 20
A43: DEPILACIONES | B43: 220.5 | C43: 1 | D43: =S43*$C$43*$B$43 -> 13230 | E43: =T43*$C$43*$B$43 -> 16978.5 | F43: =U43*$C$43*$B$43 -> 22050 | G43: =V43*$C$43*$B$43 -> 19845 | H43: =W43*$C$43*$B$43 -> 17640 | I43: =X43*$C$43*$B$43 -> 13230 | J43: =Y43*$C$43*$B$43 -> 17640 | K43: =Z43*$C$43*$B$43 -> 14332.5 | ... O43: =AD43*$C$43*$B$43 -> 8820 | P43: =SUM(D43:O43) -> 187866 | S43: 60 | T43: 77 | U43: 100 | V43: 90 | W43: 80 | X43: 60 | Y43: 80 | Z43: 65 | AA43: 75 | AB43: 75 | AC43: 50 | AD43: 40
A44: APAR. 50% (CONTADO) | B44: =3307.5/2 -> 1653.75 | C44: 1 | D44: =S44*$C$44*$B$44 -> 8268.75 | E44: =T44*$C$44*$B$44 -> 6615 | F44: =U44*$C$44*$B$44 -> 4961.25 | G44: =V44*$C$44*$B$44 -> 6615 | H44: =W44*$C$44*$B$44 -> 4961.25 | I44: =X44*$C$44*$B$44 -> 3307.5 | J44: =Y44*$C$44*$B$44 -> 3307.5 | K44: =Z44*$C$44*$B$44 -> 4961.25 | ... O44: =AD44*$C$44*$B$44 -> 3307.5 | P44: =SUM(D44:O44) -> 66150 | S44: 5 | T44: 4 | U44: 3 | V44: 4 | W44: 3 | X44: 2 | Y44: 2 | Z44: 3 | AA44: 4 | AB44: 5 | AC44: 3 | AD44: 2
A45: APAR. 50% (15 DÍAS) | B45: =B44 -> 1653.75 | C45: 1 | D45: =O26 -> 6300 | E45: =D44 -> 8268.75 | F45: =E44 -> 6615 | G45: =F44 -> 4961.25 | H45: =G44 -> 6615 | I45: =H44 -> 4961.25 | J45: =I44 -> 3307.5 | K45: =J44 -> 3307.5 | L45: =K44 -> 4961.25 | ... O45: =N44 -> 4961.25 | P45: =SUM(D45:O45) -> 69142.5
A46: SESIONES APARTO. | B46: 385.88 | C46: 1 | D46: =S46*$C$46*$B$46 -> 9647 | E46: =T46*$C$46*$B$46 -> 8489.36 | F46: =U46*$C$46*$B$46 -> 11576.4 | G46: =V46*$C$46*$B$46 -> 7717.6 | H46: =W46*$C$46*$B$46 -> 11576.4 | I46: =X46*$C$46*$B$46 -> 6945.84 | J46: =Y46*$C$46*$B$46 -> 7717.6 | K46: =Z46*$C$46*$B$46 -> 9647 | ... O46: =AD46*$C$46*$B$46 -> 11576.4 | P46: =SUM(D46:O46) -> 84893.6 | S46: 25 | T46: 22 | U46: 30 | V46: 20 | W46: 30 | X46: 18 | Y46: 20 | Z46: 25 | AA46: 0 | AB46: 0 | AC46: 0 | AD46: 30
A47: RADIO FACIAL | B47: 275.63 | C47: 1 | D47: =S47*$C$47*$B$47 -> 6890.75 | E47: =T47*$C$47*$B$47 -> 8268.9 | F47: =U47*$C$47*$B$47 -> 6615.12 | G47: =V47*$C$47*$B$47 -> 8268.9 | H47: =W47*$C$47*$B$47 -> 11025.2 | I47: =X47*$C$47*$B$47 -> 6890.75 | J47: =Y47*$C$47*$B$47 -> 11025.2 | K47: =Z47*$C$47*$B$47 -> 8268.9 | ... O47: =AD47*$C$47*$B$47 -> 12403.35 | P47: =SUM(D47:O47) -> 115488.97 | S47: 25 | T47: 30 | U47: 24 | V47: 30 | W47: 40 | X47: 25 | Y47: 40 | Z47: 30 | AA47: 60 | AB47: 35 | AC47: 35 | AD47: 45
...

Sheet Flujos
A1: 2020
B2: ENE | C2: FEB | D2: MAR | E2: ABR | F2: MAY | G2: JUN | H2: JUL | I2: AGO | J2: SEP | K2: OCT | L2: NOV | M2: DIC | N2: TOTAL
A3: SALDO INICIAL | B3: 43154 | C3: =B18+B19 -> 34982.96 | D3: =C19+C18 -> 45640.76 | E3: =D18+D19 -> 67542.76 | F3: =E19+E18 -> 76182.3 | G3: =F18+F19 -> 82123.98 | H3: =G18+G19 -> 80096.58 | I3: =H18+H19 -> 77909.78 | J3: =I18+I19 -> 90093.58 | K3: =J18+J19 -> 109200.06 | L3: =K18+K19 -> 121938.46 | M3: =L18+L19 -> 129216.26 | N3: =SUM(B3:M3) -> 958081.48
A4: ENTRADAS DE EFECTIVO
A5: VENTA-SERVICIO | B5: =VENTAS!D13 -> 45200 | C5: =VENTAS!E13 -> 71050 | D5: =VENTAS!F13 -> 77800 | E5: =VENTAS!G13 -> 62400 | F5: =VENTAS!H13 -> 67900 | G5: =VENTAS!I13 -> 52300 | H5: =VENTAS!J13 -> 52050 | I5: =VENTAS!K13 -> 64200 | ... M5: =VENTAS!O13 -> 69700 | N5: =SUM(B5:M5) -> 778250
A6: TOTAL DE INGRESOS | B6: =B5+B3 -> 88354 | C6: =C5+C3 -> 106032.96 | D6: =D5+D3 -> 123440.76 | E6: =E5+E3 -> 129942.76 | F6: =F5+F3 -> 144082.3 | G6: =G5+G3 -> 134423.98 | H6: =H5+H3 -> 132146.58 | I6: =I5+I3 -> 142109.78 | ... M6: =M5+M3 -> 198916.26 | N6: =SUM(B6:M6) -> 1736331.5
A7: SALIDAS DE EFECTIVO
A8: LUZ(BIM) | B8: 0 | C8: 1800 | D8: 0 | E8: 1800 | F8: 0 | G8: 1800 | H8: 0 | I8: 1800 | J8: 0 | K8: 1800 | L8: 0 | M8: 1800 | N8: =SUM(B8:M8) -> 10800
A9: AGUA(BIM) | B9: 250 | C9: 320 | D9: 240 | E9: 250 | F9: 320 | G9: 250 | H9: 240 | I9: 250 | J9: 250 | K9: 320 | L9: 250 | M9: 350 | N9: =SUM(B9:M9) -> 3290
A10: TELEFONO E INTERNET | B10: 1000 | C10: 349 | D10: 349 | E10: 349 | F10: 349 | G10: 349 | H10: 349 | I10: 349 | J10: 349 | K10: 349 | L10: 349 | M10: 349 | N10: =SUM(B10:M10) -> 4839
A11: RENTA | B11: 18000 | C11: 9000 | D11: 9000 | E11: 9000 | F11: 9000 | G11: 9000 | H11: 9000 | I11: 9000 | J11: 9000 | K11: 9000 | L11: 9000 | M11: 9000 | N11: =SUM(B11:M11) -> 117000
A12: SEGURIDAD | B12: 0 | C12: 0 | D12: 0 | E12: 0 | F12: 0 | G12: 650 | H12: 0 | I12: 0 | J12: 0 | K12: 0 | L12: 0 | M12: 650 | N12: =SUM(B12:M12) -> 1300
A13: SUELDOS | B13: 19000 | C13: 19000 | D13: 19000 | E13: 19000 | F13: 19000 | G13: 19000 | H13: 19000 | I13: 19000 | J13: 19000 | K13: 19000 | L13: 19000 | M13: 19000 | N13: =SUM(B13:M13) -> 228000
A14: LAVANDERIA | B14: 544 | C14: 544 | D14: 544 | E14: 544 | F14: 544 | G14: 544 | H14: 544 | I14: 544 | J14: 544 | K14: 544 | L14: 544 | M14: 544 | N14: =SUM(B14:M14) -> 6528
A15: PAGO IMSS | B15: 0 | C15: 2800 | D15: 6000 | E15: 2800 | F15: 6000 | G15: 2800 | H15: 6000 | I15: 2800 | J15: 6000 | K15: 2800 | L15: 6000 | M15: 2800 | N15: =SUM(B15:M15) -> 46800
A16: INSUMOS | B16: 14577.04 | C16: 26579.2 | D16: 20765 | E16: 20017.46 | F16: 26745.32 | G16: 19934.4 | H16: 19103.8 | I16: 18273.2 | J16: 20100.52 | K16: 25748.6 | L16: 26579.2 | M16: 27409.8 | N16: =SUM(B16:M16) -> 265833.54
A17: SALDO ANTES DE MINIMO | B17: =B6-B8-B9-B10-B11-B12-B13-B14-B15-B16 -> 34982.96 | C17: =C6-C8-C9-C10-C11-C12-C13-C14-C15-C16 -> 45640.76 | D17: =D6-D8-D9-D10-D11-D12-D13-D14-D15-D16 -> 67542.76 | E17: =E6-E8-E9-E10-E11-E12-E13-E14-E15-E16 -> 76182.3 | F17: =F6-F8-F9-F10-F11-F12-F13-F14-F15-F16 -> 82123.98 | G17: =G6-G8-G9-G10-G11-G12-G13-G14-G15-G16 -> 80096.58 | H17: =H6-H8-H9-H10-H11-H12-H13-H14-H15-H16 -> 77909.78 | I17: =I6-I8-I9-I10-I11-I12-I13-I14-I15-I16 -> 90093.58 | ... M17: =M6-M8-M9-M10-M11-M12-M13-M14-M15-M16 -> 137013.46 | N17: =SUM(B17:M17) -> 1051940.9
A18: SALDO MINIMO DE OPERACIÓN | B18: 25000 | C18: 25000 | D18: 25000 | E18: 25000 | F18: 25000 | G18: 25000 | H18: 25000 | I18: 25000 | J18: 25000 | K18: 25000 | L18: 25000 | M18: 25000 | N18: =SUM(B18:M18) -> 300000
A19: EFECTIVO NUEVO DISPONIBLE | B19: =B17-B18 -> 9982.96 | C19: =C17-C18 -> 20640.76 | D19: =D17-D18 -> 42542.76 | E19: =E17-E18 -> 51182.3 | F19: =F17-F18 -> 57123.98 | G19: =G17-G18 -> 55096.58 | H19: =H17-H18 -> 52909.78 | I19: =I17-I18 -> 65093.58 | ... M19: =M17-M18 -> 112013.46 | N19: =N6-N8-N9-N10-N11-N12-N13-N14-N15-N16 -> 1051940.9
A21: 2021
B23: ENE | C23: FEB | D23: MAR | E23: ABR | F23: MAY | G23: JUN | H23: JUL | I23: AGO | J23: SEP | K23: OCT | L23: NOV | M23: DIC | N23: TOTAL
A24: SALDO INICIAL | B24: =M19+M18 -> 137013.46 | C24: =B41+B42 -> 130180.49 | D24: =C42+C41 -> 141635.91 | E24: =D41+D42 -> 160679.83 | F24: =E42+E41 -> 166396.04 | G24: =F41+F42 -> 186131.76 | H24: =G41+G42 -> 180374.26 | I24: =H41+H42 -> 186523.97 | J24: =I41+I42 -> 195767.64 | K24: =J41+J42 -> 212757.91 | L24: =K41+K42 -> 223066.16 | M24: =L41+L42 -> 232158.42 | N24: =SUM(B24:M24) -> 2152685.8
A25: ENTRADAS DE EFECTIVO
A26: VENTA-SERVICIO | B26: =VENTAS!D31 -> 60317.5 | C26: =VENTAS!E31 -> 78855 | D26: =VENTAS!F31 -> 92190 | E26: =VENTAS!G31 -> 77490 | F26: =VENTAS!H31 -> 94710 | G26: =VENTAS!I31 -> 58065 | H26: =VENTAS!J31 -> 75022.5 | I26: =VENTAS!K31 -> 78750 | ... M26: =VENTAS!O31 -> 80325 | N26: =SUM(B26:M26) -> 949142.5
A27: TOTAL DE INGRESOS | B27: =B26+B24 -> 197330.96 | C27: =C26+C24 -> 209035.49 | D27: =D26+D24 -> 233825.91 | E27: =E26+E24 -> 238169.83 | F27: =F26+F24 -> 261106.04 | G27: =G26+G24 -> 244196.76 | H27: =H26+H24 -> 255396.76 | I27: =I26+I24 -> 265273.97 | ... M27: =M26+M24 -> 312483.42 | N27: =SUM(B27:M27) -> 3101828.3
A28: SALIDAS DE EFECTIVO
A29: LUZ(BIM) | B29: 0 | C29: 1890 | D29: 0 | E29: 1890 | F29: 0 | G29: 1890 | H29: 0 | I29: 1890 | J29: 0 | K29: 1890 | L29: 0 | M29: 1890 | N29: =SUM(B29:M29) -> 11340
A30: AGUA(BIM) | B30: 262.5 | C30: 336 | D30: 252 | E30: 262.5 | F30: 336 | G30: 262.5 | H30: 252 | I30: 262.5 | J30: 262.5 | K30: 336 | L30: 262.5 | M30: 367.5 | N30: =SUM(B30:M30) -> 3454.5
A31: TELEFONO E INTERNET | B31: 1050 | C31: 366.45 | D31: 366.45 | E31: 366.45 | F31: 366.45 | G31: 366.45 | H31: 366.45 | I31: 366.45 | J31: 366.45 | K31: 366.45 | L31: 366.45 | M31: 366.45 | N31: =SUM(B31:M31) -> 5080.95
A32: RENTA | B32: 9450 | C32: 9450 | D32: 9450 | E32: 9450 | F32: 9450 | G32: 9450 | H32: 9450 | I32: 9450 | J32: 9450 | K32: 9450 | L32: 9450 | M32: 9450 | N32: =SUM(B32:M32) -> 113400
A33: SEGURIDAD | B33: 1682.5 | C33: 0 | D33: 0 | E33: 0 | F33: 0 | G33: 682.5 | H33: 0 | I33: 0 | J33: 0 | K33: 0 | L33: 0 | M33: 682.5 | N33: =SUM(B33:M33) -> 3047.5
A34: SUELDOS | B34: 19950 | C34: 19950 | D34: 19950 | E34: 19950 | F34: 19950 | G34: 19950 | H34: 19950 | I34: 19950 | J34: 19950 | K34: 19950 | L34: 19950 | M34: 19950 | N34: =SUM(B34:M34) -> 239400
A35: BONO PUNTUALIDAD | B35: 1575 | C35: 1575 | D35: 1575 | E35: 1575 | F35: 1575 | G35: 1575 | H35: 1575 | I35: 1575 | J35: 1575 | K35: 1575 | L35: 1575 | M35: 1575 | N35: =SUM(B35:M35) -> 18900
A36: PAGO IMSS | B36: 6300 | C36: 2940 | D36: 6300 | E36: 2940 | F36: 6300 | G36: 2940 | H36: 6300 | I36: 2940 | J36: 6300 | K36: 2940 | L36: 6300 | M36: 2940 | N36: =SUM(B36:M36) -> 55440
A37: LAVANDERIA | B37: 571.2 | C37: 571.2 | D37: 571.2 | E37: 571.2 | F37: 571.2 | G37: 571.2 | H37: 571.2 | I37: 571.2 | J37: 571.2 | K37: 571.2 | L37: 571.2 | M37: 571.2 | N37: =SUM(B37:M37) -> 6854.4
A38: IMPUESTOS | B38: 3285.83 | C38: 3285.83 | D38: 3285.83 | E38: 3285.83 | F38: 3285.83 | G38: 3285.83 | H38: 3285.83 | I38: 3285.83 | J38: 3285.83 | K38: 3285.83 | L38: 3285.83 | M38: 3285.83 | N38: =SUM(B38:M38) -> 39429.96
A39: INSUMOS | B39: 23023.44 | C39: 27035.1 | D39: 31395.6 | E39: 31482.81 | F39: 33139.8 | G39: 22849.02 | H39: 27122.31 | I39: 29215.35 | J39: 32703.75 | K39: 29389.77 | L39: 31046.76 | M39: 31308.39 | N39: =SUM(B39:M39) -> 349712.1
A40: SALDO ANTES DE MINIMO | B40: =B27-B29-B30-B31-B32-B33-B34-B35-B36-B37-B39-B38 -> 130180.49 | C40: =C27-C29-C30-C31-C32-C33-C34-C36-C37-C39-C35-C38 -> 141635.91 | D40: =D27-D29-D30-D31-D32-D33-D34-D36-D37-D39-D35-D38 -> 160679.83 | E40: =E27-E29-E30-E31-E32-E33-E34-E36-E37-E39-E35-E38 -> 166396.04 | F40: =F27-F29-F30-F31-F32-F33-F34-F36-F37-F39-F35-F38 -> 186131.76 | G40: =G27-G29-G30-G31-G32-G33-G34-G36-G37-G39-G35-G38 -> 180374.26 | H40: =H27-H29-H30-H31-H32-H33-H34-H36-H37-H39-H35-H38 -> 186523.97 | I40: =I27-I29-I30-I31-I32-I33-I34-I36-I37-I39-I35-I38 -> 195767.64 | J40: =J27-J29-J30-J31-J32-J33-J34-J36-J37-J39-J35-J38 -> 212757.91 | ... M40: =M27-M29-M30-M31-M32-M33-M34-M36-M37-M39-M35-M38 -> 240096.55 | N40: =SUM(B40:M40) -> 2255768.9
A41: SALDO MINIMO DE OPERACIÓN | B41: 26250 | C41: 26250 | D41: 26250 | E41: 26250 | F41: 26250 | G41: 26250 | H41: 26250 | I41: 26250 | J41: 26250 | K41: 26250 | L41: 26250 | M41: 26250 | N41: =SUM(B41:M41) -> 315000
A42: EFECTIVO NUEVO DISPONIBLE | B42: =B40-B41 -> 103930.49 | C42: =C40-C41 -> 115385.91 | D42: =D40-D41 -> 134429.83 | E42: =E40-E41 -> 140146.04 | F42: =F40-F41 -> 159881.76 | G42: =G40-G41 -> 154124.26 | H42: =H40-H41 -> 160273.97 | I42: =I40-I41 -> 169517.64 | ... M42: =M40-M41 -> 213846.55 | N42: =SUM(B42:M42) -> 1940768.9
...

Sheet Estado de Resultados
B2: 2020 | C2: 2021 | D2: 2022 | E2: 2023 | F2: 2024
A3: VENTAS NETAS | B3: 784650 | C3: 949042.5 | D3: =VENTAS!P51 -> 1142776.6 | E3: =VENTAS!P70 -> 1341393 | F3: =VENTAS!P89 -> 1630321.1
A4: COSTO DE VENTA | B4: 265833 | C4: 349712.1 | D4: 353917.7 | E4: 404791.5 | F4: 431009.2
A5: UTILIDAD BRUTA | B5: =B3-B4 -> 518817 | C5: =C3-C4 -> 599330.4 | D5: =D3-D4 -> 788858.92 | E5: =E3-E4 -> 936601.49 | F5: =F3-F4 -> 1199311.9
A6: GASTOS DE OPERACIÓN | B6: =SUM(B7:B16) -> 420241.6 | C6: =SUM(C7:C16) -> 467601.95 | D6: =SUM(D7:D16) -> 516907.93 | E6: =SUM(E7:E16) -> 540364.09 | F6: =SUM(F7:F16) -> 566847.98
A7: SUELDOS | B7: 228000 | C7: 239400 | D7: 277830 | E7: 291721.56 | F7: 306307.56
A8: IMSS | B8: 46800 | C8: 55440 | D8: 58212 | E8: 61122.6 | F8: 64178.73
A9: RENTA | B9: 108000 | C9: 113400 | D9: 119070 | E9: 125023.5 | F9: 131274.68
A10: DEPRECIACION (10%) | B10: 10684.6 | C10: 10684.6 | D10: 10684.6 | E10: 10684.6 | F10: 10684.6
A11: BONO DE PUNTUALIDAD | B11: 0 | C11: 18900 | D11: 19845 | E11: 20837.25 | F11: 21879.11
A12: LUZ | B12: 10800 | C12: 11340 | D12: 11907 | E12: 12502.35 | F12: 13127.47
A13: AGUA | B13: 3290 | C13: 3454.5 | D13: 3627.33 | E13: 3808.59 | F13: 3999.025
A14: SEGURIDAD | B14: 1300 | C14: 3047.5 | D14: 3199.88 | E14: 1504.91 | F14: 1580.16
A15: TEL/INTERNET | B15: 4839 | C15: 5080.95 | D15: 5335 | E15: 5601.75 | F15: 5881.83
A16: LAVANDERIA | B16: 6528 | C16: 6854.4 | D16: 7197.12 | E16: 7556.98 | F16: 7934.82
A17: UAII | B17: =B5-B6 -> 98575.4 | C17: =C5-C6 -> 131728.45 | D17: =D5-D6 -> 271950.99 | E17: =E5-E6 -> 396237.4 | F17: =F5-F6 -> 632463.94
A18: INTERESES | B18: 0 | C18: 0 | D18: 4734.84 | E18: 1753.31 | F18: 0
A19: UAI | B19: =B17-B18 -> 98575.4 | C19: =C17-C18 -> 131728.45 | D19: =D17-D18 -> 267216.15 | E19: =E17-E18 -> 394484.09 | F19: =F17-F18 -> 632463.94
A20: ISR | B20: 29572.46 | C20: 39518.54 | D20: 80164.52 | E20: 118343.14 | F20: 189712.18
A21: PTU | B21: 9857.49 | C21: 13172.85 | D21: 26721.51 | E21: 39447.71 | F21: 63237.39
A22: UDI | B22: =B19-B20-B21 -> 59145.45 | C22: =C19-C20-C21 -> 79037.06 | D22: =D19-D20-D21 -> 160330.12 | E22: =E19-E20-E21 -> 236693.24 | F22: =F19-F20-F21 -> 379514.37
A23: ACCIONES COMUNES | B23: 3 | C23: 3 | D23: 3 | E23: 3 | F23: 3
A24: UPA | B24: =B22/B23 -> 19715.15 | C24: =C22/C23 -> 26345.687 | D24: =D22/D23 -> 53443.373 | E24: =E22/E23 -> 78897.747 | F24: =F22/F23 -> 126504.79

Sheet Balance
A1: 2020
A2: ACTIVO | D2: PASIVO
A3: CIRCULANTE | B3: =B4+B5 -> 143413.46 | D3: CORTO PLAZO | E3: =E4 -> 39429.944
A4: bancos | B4: ='[1]FLUJO DE EFECTIVO'!M16 -> 137013.46 | D4: impuestos x pagar | E4: ='[1]ESTADO DE RESULTADO'!B18+'[1]ESTADO DE RESULTADO'!B19 -> 39429.944
A5: cuentas x cobrar | B5: 6400
A6: FIJO | B6: =B7+B9+B11+B13-B8-B10-B12-B14 -> 96161.4 | D6: LARGO PLAZO | E6: =E7 -> 0
A7: mob. Y equipo | B7: ='[1]tabla de inversion'!L3 -> 83025
A8: dep acum | B8: =B7*0.1 -> 8302.5 | D8: TOTAL PASIVO | E8: =E3+E6 -> 39429.944
A9: equipo computo | B9: ='[1]tabla de inversion'!L4 -> 3000
A10: dep acum | B10: =B9*0.1 -> 300 | D10: CAPITAL CONTABLE | E10: =E11+E12 -> 209144.92
A11: enseres | B11: ='[1]tabla de inversion'!L5 -> 12732 | D11: capital social | E11: 150000
A12: dep acum | B12: =B11*0.1 -> 1273.2 | D12: utilidad del ejercicio | E12: ='[1]ESTADO DE RESULTADO'!B20 -> 59144.916
A13: ep oficina | B13: ='[1]tabla de inversion'!L6 -> 8089
A14: dep acum | B14: =B13*0.1 -> 808.9 | D14: TOTAL CAPITAL | E14: =E10 -> 209144.92
A15: DIFERIDO | B15: =B16 -> 9000
A16: depositos en garantia | B16: ='[1]FLUJO DE EFECTIVO'!B10/2 -> 9000 | D16: TOTAL CAPITAL + PASIVO | E16: =E14+E8 -> 248574.86
A17: TOTAL ACTIVO | B17: =SUM(B3+B6+B15) -> 248574.86
A19: 2021
A20: ACTIVO | D20: PASIVO
A21: CIRCULANTE | B21: =B22+B23+0.02 -> 246396.57 | D21: CORTO PLAZO | E21: =E22 -> 52691.38
A22: bancos | B22: ='[1]FLUJO DE EFECTIVO'!M37 -> 240096.55 | D22: impuestos x pagar | E22: ='[1]ESTADO DE RESULTADO'!B42+'[1]ESTADO DE RESULTADO'!B43 -> 52691.38
A23: cuentas x cobrar | B23: 6300
A24: FIJO | B24: =B25+B27+B29+B31-B26-B28-B30-B32 -> 85476.8 | D24: LARGO PLAZO | E24: =E25 -> 0
A25: mob. Y equipo | B25: ='[1]tabla de inversion'!L3 -> 83025
A26: dep acum | B26: =(B25*0.1)*2 -> 16605 | D26: TOTAL PASIVO | E26: =E21+E24 -> 52691.38
A27: equipo computo | B27: ='[1]tabla de inversion'!L4 -> 3000
A28: dep acum | B28: =(B27*0.1)*2 -> 600 | D28: CAPITAL CONTABLE | E28: =E29+E30 -> 288181.99
A29: enseres | B29: ='[1]tabla de inversion'!L5 -> 12732 | D29: capital social | E29: 150000
A30: dep acum | B30: =(B29*0.1)*2 -> 2546.4 | D30: utilidad del ejercicio | E30: ='[1]ESTADO DE RESULTADO'!B44+E12 -> 138181.99
A31: ep oficina | B31: ='[1]tabla de inversion'!L6 -> 8089
A32: dep acum | B32: =(B31*0.1)*2 -> 1617.8 | D32: TOTAL CAPITAL | E32: =E28 -> 288181.99
A33: DIFERIDO | B33: =B34 -> 9000
A34: depositos en garantia | B34: 9000 | D34: TOTAL CAPITAL + PASIVO | E34: =E32+E26 -> 340873.37
A35: TOTAL ACTIVO | B35: =SUM(B21+B24+B33) -> 340873.37
A37: 2022
A38: ACTIVO | D38: PASIVO
A39: CIRCULANTE | B39: =B40+B41+0.02 -> 498090.77 | D39: CORTO PLAZO | E39: =E40+E41 -> 133374.87
A40: bancos | B40: ='[1]FLUJO DE EFECTIVO'!M60-6.06 -> 494783.25 | D40: impuestos x pagar | E40: ='[1]ESTADO DE RESULTADO'!B66+'[1]ESTADO DE RESULTADO'!B67-2+0.05 -> 106884.07
A41: cuentas x cobrar | B41: 3307.5 | D41: prestamo | E41: =50000-'[1]FLUJO DE EFECTIVO'!N58 -> 26490.8
A42: FIJO | B42: =B43+B45+B47+B49-B44-B46-B48-B50 -> 74792.2
...

Sheet Punto Equilibrio
A1: 2020
A2: Precio Venta | B2: 605.56
A3: Costo Venta | B3: 83.06 | C3: Punto Equilibrio | D3: =B4/(B2-B3) -> 783.84115
A4: Costos Fijos | B4: ='Estado de Resultados'!B6-'Estado de Resultados'!B10 -> 409557
A7: 2021
A8: Precio Venta | B8: 635.83
A9: Costo Venta | B9: 87.21 | C9: Punto Equilibrio | D9: =B10/(B8-B9) -> 813.3731
A10: Costos Fijos | B10: ='Estado de Resultados'!C6-'Estado de Resultados'!C10-'Estado de Resultados'!B10 -> 446232.75
A13: 2022
A14: Precio Venta | B14: 612.41
A15: Costo Venta | B15: 91.57 | C15: Punto Equilibrio | D15: =B16/(B14-B15) -> 971.93635
A16: Costos Fijos | B16: ='Estado de Resultados'!D6-'Estado de Resultados'!D10 -> 506223.33
A19: 2023
A20: Precio Venta | B20: 637.07
A21: Costo Venta | B21: 96.15 | C21: Punto Equilibrio | D21: =B22/(B20-B21) -> 979.21964
A22: Costos Fijos | B22: ='Estado de Resultados'!E6-'Estado de Resultados'!E10 -> 529679.49
A25: 2024
A26: Precio Venta | B26: 668.93
A27: Costo Venta | B27: 100.96 | C27: Punto Equilibrio | D27: =B28/(B26-B27) -> 979.21261
A28: Costos Fijos | B28: ='Estado de Resultados'!F6-'Estado de Resultados'!F10 -> 556163.38

Sheet Razones Financieras
E1: 2020 | F1: 2021 | G1: 2022 | H1: 2023 | I1: 2024
A3: Capital de trabajo | B3: Activo Circulante-Pasivo Corto Plazo | E3: =Balance!B3-Balance!E3 -> 103983.52 | F3: =Balance!B21-Balance!E21 -> 193705.19 | G3: =Balance!B39-Balance!E39 -> 364715.9 | H3: =Balance!B57-Balance!E57 -> 612099.4 | I3: =Balance!B75-Balance!E75 -> 1002195.8
A4: Liquidez | B4: Activo Circulante/Pasivo Corto Plazo | E4: =Balance!B3/Balance!E3 -> 3.6371713 | F4: =Balance!B21/Balance!E21 -> 4.6762216 | G4: =Balance!B39/Balance!E39 -> 3.7345174 | H4: =Balance!B57/Balance!E57 -> 4.8791816 | I4: =Balance!B75/Balance!E75 -> 4.9620378
A7: Rotacion de Clientes | B7: Ventas a credito/Promedio Cuentas por Cobrar | E7: =VENTAS!P8/Balance!B5 -> 14 | F7: =VENTAS!P26/Balance!B23 -> 13.75 | G7: =VENTAS!P44/Balance!H45 -> 13.770492 | H7: =VENTAS!P63/Balance!H65 -> 16.718456 | I7: =VENTAS!P82/Balance!H79 -> 15.16666
A8: Dias cliente | B8: 30 días/Rotacion CxC | E8: =30/E7 -> 2.1428571 | F8: =30/F7 -> 2.1818182 | G8: =30/G7 -> 2.1785714 | H8: =30/H7 -> 1.7944241 | I8: =30/I7 -> 1.9780229
A9: Rotación de Activos | B9: Ventas/Activos Totales | E9: ='Estado de Resultados'!B3/Balance!B17 -> 3.1565944 | F9: ='Estado de Resultados'!C3/Balance!B35 -> 2.7841497 | G9: ='Estado de Resultados'!D3/Balance!B53 -> 1.9639287 | H9: ='Estado de Resultados'!E3/Balance!B71 -> 1.5912413 | I9: ='Estado de Resultados'!F3/Balance!B89 -> 1.2373741
A12: Razon de dependencia financiera | B12: Pasivo total/Activo Total | E12: =Balance!E8/Balance!B17 -> 0.15862402 | F12: =Balance!E26/Balance!B35 -> 0.15457758 | G12: =Balance!E44/Balance!B53 -> 0.22921254 | H12: =Balance!E62/Balance!B71 -> 0.18718104 | I12: =Balance!E80/Balance!B89 -> 0.19198258
A13: Razon Pasivo Capital | B13: Pasivo total/Capital Contable | E13: =Balance!E8/Balance!E14 -> 0.1885293 | F13: =Balance!E26/Balance!E28 -> 0.18284064 | G13: =Balance!E44/Balance!E46 -> 0.29737451 | H13: =Balance!E62/Balance!E64 -> 0.23028626 | I13: =Balance!E80/Balance!E82 -> 0.23759675
A14: Razon Cobertura Interes | B14: UAII/Gastos por interes | E14: ='Estado de Resultados'!B17/0 -> #DIV/0! | F14: ='Estado de Resultados'!C17/'Estado de Resultados'!C18 -> #DIV/0! | G14: ='Estado de Resultados'!D17/'Estado de Resultados'!D18 -> 57.436152 | H14: ='Estado de Resultados'!E17/'Estado de Resultados'!E18 -> 225.99392 | I14: ='Estado de Resultados'!F17/'Estado de Resultados'!F18 -> #DIV/0!
A15: Razon Inversion Propia | B15: Capital contable/Activo Total | E15: =Balance!E10/Balance!B17 -> 0.84137598 | F15: =Balance!E28/Balance!B35 -> 0.84542241 | G15: =Balance!E46/Balance!B53 -> 0.77078747 | H15: =Balance!E64/Balance!B71 -> 0.81281896 | I15: =Balance!E82/Balance!B89 -> 0.80801853
A18: Rendimiento de la inversion | B18: Utilidad Neta Despues Imptos/Activos Totales | E18: ='Estado de Resultados'!B22/Balance!B17 -> 0.23793818 | F18: ='Estado de Resultados'!C22/Balance!B35 -> 0.23186634 | G18: ='Estado de Resultados'!D22/Balance!B53 -> 0.27553672 | H18: ='Estado de Resultados'!E22/Balance!B71 -> 0.28077981 | I18: ='Estado de Resultados'!F22/Balance!B89 -> 0.28804218
A19: Rendimiento del capital | B19: Utilidad Neta Depues Imptos/Capital Social | E19: ='Estado de Resultados'!B22/Balance!E11 -> 0.394303 | F19: ='Estado de Resultados'!C22/Balance!E29 -> 0.52691373 | G19: ='Estado de Resultados'!D22/Balance!E47 -> 1.0688675 | H19: ='Estado de Resultados'!E22/Balance!E65 -> 1.5779549 | I19: ='Estado de Resultados'!F22/Balance!E83 -> 2.5300958
A20: Margen Utilidad | B20: Utilidad Neta Despues Imptos/Ventas Netas | E20: ='Estado de Resultados'!B22/'Estado de Resultados'!B3 -> 0.07537813 | F20: ='Estado de Resultados'!C22/'Estado de Resultados'!C3 -> 0.083280844 | G20: ='Estado de Resultados'!D22/'Estado de Resultados'!D3 -> 0.14029874 | H20: ='Estado de Resultados'!E22/'Estado de Resultados'!E3 -> 0.17645332 | I20: ='Estado de Resultados'!F22/'Estado de Resultados'!F3 -> 0.23278504

Sheet Evaluacion Financiera
A1: PRI | B1: 2020 | C1: 2021 | D1: 2022 | E1: 2023 | F1: 2024
A2: Bancos | B2: =Balance!B4 -> 137013.46 | C2: =Balance!B22 -> 240096.55 | D2: =Balance!B40 -> 494783.25 | E2: =Balance!B58 -> 764680.92 | F2: =Balance!B76 -> 1247852.3 | H2: La inversión regresa en un lapso de 12 meses y 19 días
A3: Inversion | B3: 150000 | G3: =B3-B2 -> 12986.54
G4: =(G3*12)/C2 -> 0.64906589
G5: =G4*30 -> 19.471977 | H5: dias
A7: TCR | B7: 2020 | C7: 2021 | D7: 2022 | E7: 2023 | F7: 2024
A8: Utilidad N | B8: ='Estado de Resultados'!B22 -> 59145.45 | C8: ='Estado de Resultados'!C22 -> 79037.06 | D8: ='Estado de Resultados'!D22 -> 160330.12 | E8: ='Estado de Resultados'!E22 -> 236693.24 | F8: ='Estado de Resultados'!F22 -> 379514.37
A9: Promedio | B9: =AVERAGE(B8:F8) -> 182944.05
A10: Inv Inicial | B10: 150000
A12: TCR | B12: =B9/B10 -> 1.219627
A16: TIR
A17: INV | B17: -150000 | C17: -150000 | E17: TREMA | F17: 0.22
A18: FLUJOS 2020 | B18: =Flujos!M17 -> 137013.46 | C18: =(B18)/(1+$F$17)^1 -> 112306.11
A19: 2021 | B19: =Flujos!M40 -> 240096.55 | C19: =(B19)/(1+$F$17)^2 -> 161311.84
A20: 2022 | B20: =Flujos!M66 -> 494788.94 | C20: =(B20)/(1+$F$17)^3 -> 272483.68
A21: 2023 | B21: =Flujos!M92 -> 764671.73 | C21: =(B21)/(1+$F$17)^4 -> 345172.12
A22: 2024 | B22: =Flujos!M118 -> 1247855.6 | C22: =(B22)/(1+$F$17)^5 -> 461705.63
A23: TIR | B23: =IRR(B17:B22) -> 1.5511231
